<?xml version='1.0'?>
<sdf version='1.4'>
  <model name="cam_Rover">
  <static>false</static>

  <link name='chassis'>
            <pose>0 0 .1 0 0 0</pose>

            <collision name='collision'>
              <geometry>
                <box>
                  <size>.4 .2 .1</size>
                </box>
              </geometry>
            </collision>

            <visual name='visual'>
              <geometry>
                <box>
                  <size>.4 .2 .1</size>
                </box>
              </geometry>
            </visual>
            <collision name='caster_collision'>
            <pose>-0.15 0 -0.05 0 0 0</pose>
            <geometry>
                <sphere>
                <radius>.05</radius>
              </sphere>
            </geometry>

            <surface>
              <friction>
                <ode>
                  <mu>0</mu>
                  <mu2>0</mu2>
                  <slip1>1.0</slip1>
                  <slip2>1.0</slip2>
                </ode>
              </friction>
            </surface>
          </collision>

          <visual name='caster_visual'>
            <pose>-0.15 0 -0.05 0 0 0</pose>
            <geometry>
              <sphere>
                <radius>.05</radius>
              </sphere>
            </geometry>
          </visual>
          </link>
          <link name="camera_link">
  <pose>0.19 0 0.16 0 0 0</pose>

   
  <visual name="camera_visual">
    <pose>-0.005 0 0 0 0 0</pose>
    <geometry>
      <box>
        <size>0.015 0.08 0.022</size>
      </box>
    </geometry>
    <material>
      <ambient>0 0 0 1.0</ambient>
      <diffuse>0 0 0 1.0</diffuse>
      <specular>0.0 0.0 0.0 1.0</specular>
      <emissive>0.0 0.0 0.0 1.0</emissive>
    </material>
  </visual>    
   
  <sensor name="depth_camera" type="camera">
    <always_on>true</always_on>
    <visualize>true</visualize>
    <update_rate>5</update_rate>
    <camera name="camera">
      <horizontal_fov>1.02974</horizontal_fov>
      <image>
        <width>640</width>
        <height>480</height>
        <format>R8G8B8</format>
      </image>
      <clip>
        <near>0.02</near>
        <far>10</far>
      </clip>
      <noise>
        <type>gaussian</type>
        <!-- Noise is sampled independently per pixel on each frame.
             That pixel's noise value is added to each of its color
              channels, which at that point lie in the range [0,1]. -->
        <mean>0.0</mean>
        <stddev>0.007</stddev>
      </noise>
    </camera>
      <plugin name="camera_plugin" filename="libgazebo_ros_openni_kinect.so">
          <baseline>0.2</baseline>
          <alwaysOn>true</alwaysOn>
          <!-- Keep this zero, update_rate in the parent <sensor> tag
            will control the frame rate. -->
          <updateRate>0.0</updateRate>
          <cameraName>camera_ir</cameraName>
          <imageTopicName>/camera/color/image_raw</imageTopicName>
          <cameraInfoTopicName>/camera/color/camera_info</cameraInfoTopicName>
          <depthImageTopicName>/camera/depth/image_raw</depthImageTopicName>
          <depthImageCameraInfoTopicName>/camera/depth/camera_info</depthImageCameraInfoTopicName>
          <pointCloudTopicName>/camera/depth/points</pointCloudTopicName>
          <frameName>camera_link</frameName>
          <pointCloudCutoff>0.5</pointCloudCutoff>
          <pointCloudCutoffMax>3.0</pointCloudCutoffMax>
          <distortionK1>0</distortionK1>
          <distortionK2>0</distortionK2>
          <distortionK3>0</distortionK3>
          <distortionT1>0</distortionT1>
          <distortionT2>0</distortionT2>
          <CxPrime>0</CxPrime>
          <Cx>0</Cx>
          <Cy>0</Cy>
          <focalLength>0</focalLength>
          <hackBaseline>0</hackBaseline>
        </plugin>
  </sensor>
  </link>
          <link name="left_joint">
        <pose>0.1 0.13 0.1 0 1.5707 1.5707</pose>

        <collision name="collision">
          <geometry>
            <cylinder>
              <radius>.1</radius>
              <length>.05</length>
            </cylinder>
          </geometry>
        </collision>
        <visual name="visual">
          <geometry>
            <cylinder>
              <radius>.1</radius>
              <length>.05</length>
            </cylinder>
          </geometry>
        </visual>
      </link>
      <link name="right_joint">
        <pose>0.1 -0.13 0.1 0 1.5707 1.5707</pose>
        <collision name="collision">
          <geometry>
            <cylinder>
              <radius>.1</radius>
              <length>.05</length>
            </cylinder>
          </geometry>
        </collision>
        <visual name="visual">
          <geometry>
            <cylinder>
              <radius>.1</radius>
              <length>.05</length>
            </cylinder>
          </geometry>
        </visual>
      </link>
      <joint type="fixed" name="camera_joint">
        <pose>0 0 0 0 0 0</pose>
        <child>camera_link</child>
        <parent>chassis</parent>
        <axis>
          <xyz>0 1 0</xyz>
        </axis>
      </joint>
<joint type="revolute" name="left_wheel_joint">
        <pose>0 0 -0.03 0 0 0</pose>
        <child>left_joint</child>
        <parent>chassis</parent>
        <axis>
          <xyz>0 1 0</xyz>
        </axis>
      </joint>
      <joint type="revolute" name="right_wheel_joint">
        <pose>0 0 0.03 0 0 0</pose>
        <child>right_joint</child>
        <parent>chassis</parent>
        <axis>
          <xyz>0 1 0</xyz>
        </axis>
      </joint>
  </model>
</sdf>
